<?xml version="1.0"?>
<robot name="diff_bot" xmlns:xacro="http://www.ros.org/wiki/xacro">

  <!-- ================================================================ -->
  <!--  Parameters  — edit to match your robot                           -->
  <!-- ================================================================ -->
  <xacro:property name="base_length"      value="0.400"/>
  <xacro:property name="base_width"       value="0.350"/>
  <xacro:property name="base_height"      value="0.10"/>
  <xacro:property name="wheel_radius"     value="0.033"/>
  <xacro:property name="wheel_thickness"  value="0.020"/>
  <xacro:property name="wheel_separation" value="0.310"/>

  <!-- Sensor offsets -->
  <xacro:property name="lidar_height"     value="0.01"/>  <!-- LiDAR body half-height -->
  <xacro:property name="imu_size"         value="0.025"/>  <!-- IMU box side length -->

  <!-- ================================================================ -->
  <!--  Links & Joints                                                    -->
  <!-- ================================================================ -->
  <link name="base_footprint"/>

  <joint name="base_joint" type="fixed">
    <parent link="base_footprint"/>
    <child  link="base_link"/>
    <origin xyz="0 0 ${wheel_radius + 0.04}" rpy="0 0 0"/>
  </joint>

  <link name="base_link">
    <visual>
      <geometry><box size="${base_length} ${base_width} ${base_height}"/></geometry>
      <material name="blue"><color rgba="0.2 0.4 0.8 1.0"/></material>
    </visual>
    <collision>
      <geometry><box size="${base_length} ${base_width} ${base_height}"/></geometry>
    </collision>
    <inertial>
      <mass value="1.0"/>
      <inertia ixx="0.005" ixy="0" ixz="0" iyy="0.005" iyz="0" izz="0.005"/>
    </inertial>
  </link>

  <xacro:macro name="wheel" params="name y_reflect">
    <link name="${name}">
      <visual>
        <geometry><cylinder radius="${wheel_radius}" length="${wheel_thickness}"/></geometry>
        <origin xyz="0 0 0" rpy="${pi/2} 0 0"/>
        <material name="black"><color rgba="0.1 0.1 0.1 1.0"/></material>
      </visual>
      <collision>
        <geometry><cylinder radius="${wheel_radius}" length="${wheel_thickness}"/></geometry>
        <origin xyz="0 0 0" rpy="${pi/2} 0 0"/>
      </collision>
      <inertial>
        <mass value="0.2"/>
        <inertia ixx="0.0001" ixy="0" ixz="0" iyy="0.0001" iyz="0" izz="0.0002"/>
      </inertial>
    </link>
    <joint name="${name}_joint" type="continuous">
      <parent link="base_link"/>
      <child  link="${name}"/>
      <origin xyz="0 ${y_reflect * wheel_separation / 2} -0.04" rpy="0 0 0"/>
      <axis xyz="0 1 0"/>
    </joint>
  </xacro:macro>

  <xacro:wheel name="left_wheel"  y_reflect=" 1"/>
  <xacro:wheel name="right_wheel" y_reflect="-1"/>

  <!-- Caster -->
  <link name="caster_link">
    <visual>
      <geometry><sphere radius="${wheel_radius / 2}"/></geometry>
      <material name="grey"><color rgba="0.5 0.5 0.5 1.0"/></material>
    </visual>
    <collision><geometry><sphere radius="${wheel_radius / 2}"/></geometry></collision>
    <inertial>
      <mass value="0.05"/>
      <inertia ixx="0.00001" ixy="0" ixz="0" iyy="0.00001" iyz="0" izz="0.00001"/>
    </inertial>
  </link>
  <joint name="caster_joint" type="fixed">
    <parent link="base_link"/>
    <child  link="caster_link"/>
    <origin xyz="${base_length/2 - 0.02} 0 ${-wheel_radius/2}" rpy="0 0 0"/>
  </joint>

  <!-- ================================================================ -->
  <!--  IMU                                                               -->
  <!--  Centered on top of base. Frame aligned with base_link (no rpy). -->
  <!--  Edit xyz to match your physical mounting position.               -->
  <!-- ================================================================ -->
  <link name="imu_link">
    <visual>
      <geometry><box size="${imu_size} ${imu_size} 0.010"/></geometry>
      <material name="green"><color rgba="0.0 0.8 0.2 1.0"/></material>
    </visual>
    <collision>
      <geometry><box size="${imu_size} ${imu_size} 0.010"/></geometry>
    </collision>
    <inertial>
      <mass value="0.010"/>
      <inertia ixx="0.000001" ixy="0" ixz="0" iyy="0.000001" iyz="0" izz="0.000001"/>
    </inertial>
  </link>
  <joint name="imu_joint" type="fixed">
    <parent link="base_link"/>
    <child  link="imu_link"/>
    <!-- Sits on top of the base, centered -->
    <origin xyz="0 0 0.005" rpy="0 0 0"/>
  </joint>

  <!-- ================================================================ -->
  <!--  LiDAR                                                             -->
  <!--  Mounted forward-center on top of base. Adjust xyz as needed.    -->
  <!--  The laser scan plane is at z=0 of lidar_link by convention.     -->
  <!-- ================================================================ -->
  <link name="lidar_link">
    <visual>
      <geometry><cylinder radius="0.035" length="${lidar_height * 2}"/></geometry>
      <material name="black"><color rgba="0.1 0.1 0.1 1.0"/></material>
    </visual>
    <collision>
      <geometry><cylinder radius="0.035" length="${lidar_height * 2}"/></geometry>
    </collision>
    <inertial>
      <mass value="0.150"/>
      <inertia ixx="0.0001" ixy="0" ixz="0" iyy="0.0001" iyz="0" izz="0.0001"/>
    </inertial>
  </link>
  <joint name="lidar_joint" type="fixed">
    <parent link="base_link"/>
    <child  link="lidar_link"/>
    <!-- Forward-center, scan plane level with top of lidar body -->
    <origin xyz="0 0 ${base_height/2 + lidar_height}" rpy="0 0 0"/>
  </joint>

  <!-- ================================================================ -->
  <!--  ros2_control hardware interface block                             -->
  <!-- ================================================================ -->
  <ros2_control name="esp32_hardware" type="system">
    <hardware>
      <plugin>esp32_hardware/Esp32HardwareInterface</plugin>
      <param name="serial_port">/dev/serial/by-id/usb-1a86_USB_Serial-if00-port0</param>
      <param name="baud_rate">921600</param>
    </hardware>

    <joint name="left_wheel_joint">
      <command_interface name="velocity">
        <param name="min">-9.0</param>
        <param name="max"> 9.0</param>
      </command_interface>
      <state_interface name="position"/>
      <state_interface name="velocity"/>
    </joint>

    <joint name="right_wheel_joint">
      <command_interface name="velocity">
        <param name="min">-9.0</param>
        <param name="max"> 9.0</param>
      </command_interface>
      <state_interface name="position"/>
      <state_interface name="velocity"/>
    </joint>
  </ros2_control>

</robot>